Workbook

Sheet Read Me
A1: 12-Month Running + Kettlebell Plan | Oct 1, 2026 → Oct 3, 2027
A2: Goal: general fitness and fun — be able to run anything from 5K to the half marathon in 2027. Lighter training in Nov–Dec for family time.
A4: WEEKLY TEMPLATE (Build weeks)
A5: Sun — Rest from running + KB A: Hinge & Press (strength)
A6: Mon — Quality 1: Threshold
A7: Tue — Easy Zone 2 (strides on A/even weeks) + KB B: Upper & Core (after the run, or at lunch/desk breaks)
A8: Wed — Quality 2: VO2 Max (A weeks) or Sprints/Strides (B weeks) — no kettlebell
A9: Thu — No running + KB C: Squat, Single-Leg & Carry (moderate legs)
A10: Fri — Easy Zone 2 + 4–5 strides (shakeout before long run)
A11: Sat — Long run, easy (ramps to 90')
A13: PHASES
A14: 1 Re-Entry Base (Oct 1 – Nov 1): ease back in, all 4 intensities introduced gently, long run 55–65'.
... A36: • Hill sprints need a hill; use flat accelerations if you don't have one. Anything sharp or lingering (Achilles, shin, calf, knee) → back off and get it checked.

Sheet Weekly Summary
A1: Weekly Summary — 12-Month Running + Kettlebell Plan
A2: Run Days, Total Run Min and Long Run are formulas pulling from the Daily Schedule tab. Green rows = down/holiday weeks, gold = race/test weeks.
A3: KB Sessions counts Mon/Wed/Fri kettlebell work (2 × 25 lb).
A4: Week | B4: Start (Mon) | C4: End (Sun) | D4: Phase | E4: Week Type | F4: Quality Mix | G4: Run Days | H4: Total Run Min | I4: Long Run Min (Sun) | J4: Long Run Δ vs Prior Wk | K4: KB Sessions | L4: Focus / Notes
A5: 0 | B5: 46296 | C5: 46299 | D5: 1 Re-Entry Base | E5: Start (partial week) | F5: None (restart) | G5: =COUNTIFS('Daily Schedule'!$A$5:$A$372,A5,'Daily Schedule'!$F$5:$F$372,">0") -> 3 | H5: =SUMIFS('Daily Schedule'!$F$5:$F$372,'Daily Schedule'!$A$5:$A$372,A5) -> 115 | I5: =SUMIFS('Daily Schedule'!$F$5:$F$372,'Daily Schedule'!$A$5:$A$372,A5,'Daily Schedule'!$C$5:$C$372,"Sun") -> 55 | J5: — | K5: =COUNTIFS('Daily Schedule'!$A$5:$A$372,A5,'Daily Schedule'!$I$5:$I$372,"KB*") -> 1 | L5: Partial week (Thu–Sun).
A6: 1 | B6: 46300 | C6: 46306 | D6: 1 Re-Entry Base | E6: Build | F6: Threshold + Sprints/Strides | G6: =COUNTIFS('Daily Schedule'!$A$5:$A$372,A6,'Daily Schedule'!$F$5:$F$372,">0") -> 5 | H6: =SUMIFS('Daily Schedule'!$F$5:$F$372,'Daily Schedule'!$A$5:$A$372,A6) -> 192 | I6: =SUMIFS('Daily Schedule'!$F$5:$F$372,'Daily Schedule'!$A$5:$A$372,A6,'Daily Schedule'!$C$5:$C$372,"Sun") -> 60 | J6: =I6-I5 -> 5 | K6: =COUNTIFS('Daily Schedule'!$A$5:$A$372,A6,'Daily Schedule'!$I$5:$I$372,"KB*") -> 3 | L6: Rebuild tendon/bone tolerance; controlled intro to all 4 intensities.
A7: 2 | B7: 46307 | C7: 46313 | D7: 1 Re-Entry Base | E7: Build | F7: Threshold + VO2 Max | G7: =COUNTIFS('Daily Schedule'!$A$5:$A$372,A7,'Daily Schedule'!$F$5:$F$372,">0") -> 5 | H7: =SUMIFS('Daily Schedule'!$F$5:$F$372,'Daily Schedule'!$A$5:$A$372,A7) -> 190 | I7: =SUMIFS('Daily Schedule'!$F$5:$F$372,'Daily Schedule'!$A$5:$A$372,A7,'Daily Schedule'!$C$5:$C$372,"Sun") -> 60 | J7: =I7-I6 -> 0 | K7: =COUNTIFS('Daily Schedule'!$A$5:$A$372,A7,'Daily Schedule'!$I$5:$I$372,"KB*") -> 3 | L7: Rebuild tendon/bone tolerance; controlled intro to all 4 intensities.
A8: 3 | B8: 46314 | C8: 46320 | D8: 1 Re-Entry Base | E8: Build | F8: Threshold + Sprints/Strides | G8: =COUNTIFS('Daily Schedule'!$A$5:$A$372,A8,'Daily Schedule'!$F$5:$F$372,">0") -> 5 | H8: =SUMIFS('Daily Schedule'!$F$5:$F$372,'Daily Schedule'!$A$5:$A$372,A8) -> 198 | I8: =SUMIFS('Daily Schedule'!$F$5:$F$372,'Daily Schedule'!$A$5:$A$372,A8,'Daily Schedule'!$C$5:$C$372,"Sun") -> 65 | J8: =I8-I7 -> 5 | K8: =COUNTIFS('Daily Schedule'!$A$5:$A$372,A8,'Daily Schedule'!$I$5:$I$372,"KB*") -> 3 | L8: Rebuild tendon/bone tolerance; controlled intro to all 4 intensities.
A9: 4 | B9: 46321 | C9: 46327 | D9: 1 Re-Entry Base | E9: Down week | F9: Threshold + VO2 Max | G9: =COUNTIFS('Daily Schedule'!$A$5:$A$372,A9,'Daily Schedule'!$F$5:$F$372,">0") -> 5 | H9: =SUMIFS('Daily Schedule'!$F$5:$F$372,'Daily Schedule'!$A$5:$A$372,A9) -> 167 | I9: =SUMIFS('Daily Schedule'!$F$5:$F$372,'Daily Schedule'!$A$5:$A$372,A9,'Daily Schedule'!$C$5:$C$372,"Sun") -> 55 | J9: =I9-I8 -> -10 | K9: =COUNTIFS('Daily Schedule'!$A$5:$A$372,A9,'Daily Schedule'!$I$5:$I$372,"KB*") -> 3 | L9: Down week: cut volume ~25%.
A10: 5 | B10: 46328 | C10: 46334 | D10: 2 Family-First Maintenance | E10: Maintenance | F10: Threshold only | G10: =COUNTIFS('Daily Schedule'!$A$5:$A$372,A10,'Daily Schedule'!$F$5:$F$372,">0") -> 4 | H10: =SUMIFS('Daily Schedule'!$F$5:$F$372,'Daily Schedule'!$A$5:$A$372,A10) -> 158 | I10: =SUMIFS('Daily Schedule'!$F$5:$F$372,'Daily Schedule'!$A$5:$A$372,A10,'Daily Schedule'!$C$5:$C$372,"Sun") -> 60 | J10: =I10-I9 -> 5 | K10: =COUNTIFS('Daily Schedule'!$A$5:$A$372,A10,'Daily Schedule'!$I$5:$I$372,"KB*") -> 3 | L10: Fewer run days, 1 quality session, shorter long run. Hold fitness, no big jumps. Skip freely when life happens.
A11: 6 | B11: 46335 | C11: 46341 | D11: 2 Family-First Maintenance | E11: Maintenance | F11: Short VO2 only | G11: =COUNTIFS('Daily Schedule'!$A$5:$A$372,A11,'Daily Schedule'!$F$5:$F$372,">0") -> 4 | H11: =SUMIFS('Daily Schedule'!$F$5:$F$372,'Daily Schedule'!$A$5:$A$372,A11) -> 150 | I11: =SUMIFS('Daily Schedule'!$F$5:$F$372,'Daily Schedule'!$A$5:$A$372,A11,'Daily Schedule'!$C$5:$C$372,"Sun") -> 60 | J11: =I11-I10 -> 0 | K11: =COUNTIFS('Daily Schedule'!$A$5:$A$372,A11,'Daily Schedule'!$I$5:$I$372,"KB*") -> 3 | L11: Fewer run days, 1 quality session, shorter long run. Hold fitness, no big jumps. Skip freely when life happens.
A12: 7 | B12: 46342 | C12: 46348 | D12: 2 Family-First Maintenance | E12: Maintenance | F12: Threshold only | G12: =COUNTIFS('Daily Schedule'!$A$5:$A$372,A12,'Daily Schedule'!$F$5:$F$372,">0") -> 4 | H12: =SUMIFS('Daily Schedule'!$F$5:$F$372,'Daily Schedule'!$A$5:$A$372,A12) -> 161 | I12: =SUMIFS('Daily Schedule'!$F$5:$F$372,'Daily Schedule'!$A$5:$A$372,A12,'Daily Schedule'!$C$5:$C$372,"Sun") -> 65 | J12: =I12-I11 -> 5 | K12: =COUNTIFS('Daily Schedule'!$A$5:$A$372,A12,'Daily Schedule'!$I$5:$I$372,"KB*") -> 3 | L12: Fewer run days, 1 quality session, shorter long run. Hold fitness, no big jumps. Skip freely when life happens.
A13: 8 | B13: 46349 | C13: 46355 | D13: 2 Family-First Maintenance | E13: Holiday (light) | F13: None (holiday) | G13: =COUNTIFS('Daily Schedule'!$A$5:$A$372,A13,'Daily Schedule'!$F$5:$F$372,">0") -> 3 | H13: =SUMIFS('Daily Schedule'!$F$5:$F$372,'Daily Schedule'!$A$5:$A$372,A13) -> 105 | I13: =SUMIFS('Daily Schedule'!$F$5:$F$372,'Daily Schedule'!$A$5:$A$372,A13,'Daily Schedule'!$C$5:$C$372,"Sun") -> 50 | J13: =I13-I12 -> -15 | K13: =COUNTIFS('Daily Schedule'!$A$5:$A$372,A13,'Daily Schedule'!$I$5:$I$372,"KB*") -> 3 | L13: Thanksgiving week: lightest of the fall.
A14: 9 | B14: 46356 | C14: 46362 | D14: 2 Family-First Maintenance | E14: Maintenance | F14: Threshold only | G14: =COUNTIFS('Daily Schedule'!$A$5:$A$372,A14,'Daily Schedule'!$F$5:$F$372,">0") -> 4 | H14: =SUMIFS('Daily Schedule'!$F$5:$F$372,'Daily Schedule'!$A$5:$A$372,A14) -> 158 | I14: =SUMIFS('Daily Schedule'!$F$5:$F$372,'Daily Schedule'!$A$5:$A$372,A14,'Daily Schedule'!$C$5:$C$372,"Sun") -> 60 | J14: =I14-I13 -> 10 | K14: =COUNTIFS('Daily Schedule'!$A$5:$A$372,A14,'Daily Schedule'!$I$5:$I$372,"KB*") -> 3 | L14: Fewer run days, 1 quality session, shorter long run. Hold fitness, no big jumps. Skip freely when life happens.
A15: 10 | B15: 46363 | C15: 46369 | D15: 2 Family-First Maintenance | E15: Maintenance | F15: Short VO2 only | G15: =COUNTIFS('Daily Schedule'!$A$5:$A$372,A15,'Daily Schedule'!$F$5:$F$372,">0") -> 4 | H15: =SUMIFS('Daily Schedule'!$F$5:$F$372,'Daily Schedule'!$A$5:$A$372,A15) -> 155 | I15: =SUMIFS('Daily Schedule'!$F$5:$F$372,'Daily Schedule'!$A$5:$A$372,A15,'Daily Schedule'!$C$5:$C$372,"Sun") -> 65 | J15: =I15-I14 -> 5 | K15: =COUNTIFS('Daily Schedule'!$A$5:$A$372,A15,'Daily Schedule'!$I$5:$I$372,"KB*") -> 3 | L15: Fewer run days, 1 quality session, shorter long run. Hold fitness, no big jumps. Skip freely when life happens.
A16: 11 | B16: 46370 | C16: 46376 | D16: 2 Family-First Maintenance | E16: Maintenance | F16: Threshold only | G16: =COUNTIFS('Daily Schedule'!$A$5:$A$372,A16,'Daily Schedule'!$F$5:$F$372,">0") -> 4 | H16: =SUMIFS('Daily Schedule'!$F$5:$F$372,'Daily Schedule'!$A$5:$A$372,A16) -> 161 | I16: =SUMIFS('Daily Schedule'!$F$5:$F$372,'Daily Schedule'!$A$5:$A$372,A16,'Daily Schedule'!$C$5:$C$372,"Sun") -> 65 | J16: =I16-I15 -> 0 | K16: =COUNTIFS('Daily Schedule'!$A$5:$A$372,A16,'Daily Schedule'!$I$5:$I$372,"KB*") -> 3 | L16: Fewer run days, 1 quality session, shorter long run. Hold fitness, no big jumps. Skip freely when life happens.
A17: 12 | B17: 46377 | C17: 46383 | D17: 2 Family-First Maintenance | E17: Holiday (light) | F17: None (holiday) | G17: =COUNTIFS('Daily Schedule'!$A$5:$A$372,A17,'Daily Schedule'!$F$5:$F$372,">0") -> 4 | H17: =SUMIFS('Daily Schedule'!$F$5:$F$372,'Daily Schedule'!$A$5:$A$372,A17) -> 125 | I17: =SUMIFS('Daily Schedule'!$F$5:$F$372,'Daily Schedule'!$A$5:$A$372,A17,'Daily Schedule'!$C$5:$C$372,"Sun") -> 45 | J17: =I17-I16 -> -20 | K17: =COUNTIFS('Daily Schedule'!$A$5:$A$372,A17,'Daily Schedule'!$I$5:$I$372,"KB*") -> 2 | L17: Christmas week: minimal, optional runs only.
... A57: 52 | B57: 46657 | C57: 46663 | D57: 6 Half-Marathon Block | E57: Race / test week | F57: Taper + half marathon | G57: =COUNTIFS('Daily Schedule'!$A$5:$A$372,A57,'Daily Schedule'!$F$5:$F$372,">0") -> 5 | H57: =SUMIFS('Daily Schedule'!$F$5:$F$372,'Daily Schedule'!$A$5:$A$372,A57) -> 192 | I57: =SUMIFS('Daily Schedule'!$F$5:$F$372,'Daily Schedule'!$A$5:$A$372,A57,'Daily Schedule'!$C$5:$C$372,"Sun") -> 90 | J57: =I57-I56 -> 15 | K57: =COUNTIFS('Daily Schedule'!$A$5:$A$372,A57,'Daily Schedule'!$I$5:$I$372,"KB*") -> 2 | L57: Half marathon Sun 10/3 (optional capstone). Taper week.
D59: Year totals | G59: =SUM(G5:G57) -> 253 | H59: =SUM(H5:H57) -> 10932 | K59: =SUM(K5:K57) -> 153
D60: Total run hours | H60: =H59/60 -> 182.2
D61: Avg run min / week (W1–W52) | H61: =AVERAGE(H6:H57) -> 208.01923
D62: Peak long run (min) | I62: =MAX(I5:I57) -> 90

Sheet Daily Schedule
A1: Daily Schedule — Oct 1, 2026 to Oct 3, 2027
A2: Run Min = planned total session time incl. warm-up/cool-down (optional runs counted). Weekday sessions ≤ 40'; long run ≤ 90'. Edit Run Min and the Weekly Summary updates.
A4: Week | B4: Date | C4: Day | D4: Phase | E4: Session | F4: Run Min | G4: Intensity | H4: Run Details | I4: Kettlebell | J4: Notes
A5: 0 | B5: 46295 | C5: Thu | D5: 1 Re-Entry Base | E5: Easy Run | F5: 30 | G5: Zone 2 – easy (RPE 3–4) | H5: Easy aerobic run 30' (Zone 2, talk-test pace) | I5: — | J5: Restart day. Keep it genuinely easy.
A6: 0 | B6: 46296 | C6: Fri | D6: 1 Re-Entry Base | E6: Rest (KB only) | F6: 0 | G6: — | H6: No running — kettlebell session only. | I6: KB C – intro (~20'): goblet squat 2×10 | reverse lunge 2×8 each | glute bridge 2×12 | plank 2×30s — learn the movements, easy effort
A7: 0 | B7: 46297 | C7: Sat | D7: 1 Re-Entry Base | E7: Easy Run | F7: 30 | G7: Zone 2 + strides (RPE 3–4; strides ~7) | H7: Easy aerobic run 30' (Zone 2, talk-test pace) | finish with 4×15s strides (relaxed-fast, 45–60s walk/jog between) | I7: —
A8: 0 | B8: 46298 | C8: Sun | D8: 1 Re-Entry Base | E8: Long Run | F8: 55 | G8: Zone 2 – easy (RPE 3–4) | H8: Long run 55' easy (Zone 2). Steady and relaxed — finish feeling you could run 10–15' more. | I8: — | J8: Partial week: first quality session is Tue 10/6.
A9: 1 | B9: 46299 | C9: Mon | D9: 1 Re-Entry Base | E9: Rest (KB only) | F9: 0 | G9: — | H9: No running — KB session only. Keep legs moderate (stop 2 reps shy of failure). | I9: KB A – Hinge & Press (~30', no-run day, any time): KB swings (two-hand, one 25) 3×15 | Double-KB deadlift 3×10 | Single-arm press 3×6 each | One-arm row 3×8 each | Suitcase carry 3×30s each
A10: 1 | B10: 46300 | C10: Tue | D10: 1 Re-Entry Base | E10: Quality 1: Threshold | F10: 37 | G10: Threshold – Zone 4 (RPE 6–7) | H10: WU 10' easy jog + drills | 3×5' @ threshold (2' easy jog between) | CD 8' easy | I10: — | J10: Run by effort; see Zones sheet for pace estimates.
A11: 1 | B11: 46301 | C11: Wed | D11: 1 Re-Entry Base | E11: Easy Run | F11: 30 | G11: Zone 2 – easy (RPE 3–4) | H11: Easy aerobic run 30' (Zone 2, talk-test pace) | I11: KB B – Upper & Core (~20', after the easy run, at lunch, or split into two 8–10' desk-break mini-blocks): Halos 2×8 each way | Single-arm press 3×6 each | One-arm row 3×8 each | Russian twist 3×20 | Plank 3×30s
A12: 1 | B12: 46302 | C12: Thu | D12: 1 Re-Entry Base | E12: Quality 2: Sprints/Strides | F12: 35 | G12: Sprint / neuromuscular (RPE 8–9, full recovery) | H12: WU 15' easy jog + drills | 6×15s fast strides (~85%, controlled; 60s jog recovery) | CD 12' easy | I12: — | J12: Quality over quantity: stop if form degrades. Full recovery between reps.
A13: 1 | B13: 46303 | C13: Fri | D13: 1 Re-Entry Base | E13: Rest (KB only) | F13: 0 | G13: — | H13: No running — kettlebell session only. | I13: KB C – Squat, Single-Leg & Carry (~25', no-run day, moderate legs — stop every set ~2 reps shy of failure): Goblet squat 3×10 | Reverse lunge (goblet) 2×8 each | Glute bridge (KB on hips) 3×12 | Suitcase carry 3×30s each | Plank 3×30s
A14: 1 | B14: 46304 | C14: Sat | D14: 1 Re-Entry Base | E14: Easy Run | F14: 30 | G14: Zone 2 + strides (RPE 3–4; strides ~7) | H14: Easy aerobic run 30' (Zone 2, talk-test pace) | finish with 4×15s strides (relaxed-fast, 45–60s walk/jog between) | I14: — | J14: Strides prime the legs for tomorrow's long run.
A15: 1 | B15: 46305 | C15: Sun | D15: 1 Re-Entry Base | E15: Long Run | F15: 60 | G15: Zone 2 – easy (RPE 3–4) | H15: Long run 60' easy (Zone 2). Steady and relaxed — finish feeling you could run 10–15' more. | I15: —
A16: 2 | B16: 46306 | C16: Mon | D16: 1 Re-Entry Base | E16: Rest (KB only) | F16: 0 | G16: — | H16: No running — KB session only. Keep legs moderate (stop 2 reps shy of failure). | I16: KB A – Hinge & Press (~30', no-run day, any time): KB swings (two-hand, one 25) 3×15 | Double-KB deadlift 3×10 | Single-arm press 3×6 each | One-arm row 3×8 each | Suitcase carry 3×30s each
A17: 2 | B17: 46307 | C17: Tue | D17: 1 Re-Entry Base | E17: Quality 1: Threshold | F17: 40 | G17: Threshold – Zone 4 (RPE 6–7) | H17: WU 10' easy jog + drills | 3×6' @ threshold (2' easy jog between) | CD 8' easy | I17: — | J17: Run by effort; see Zones sheet for pace estimates.
A18: 2 | B18: 46308 | C18: Wed | D18: 1 Re-Entry Base | E18: Easy Run | F18: 30 | G18: Zone 2 + strides (RPE 3–4; strides ~7) | H18: Easy aerobic run 30' (Zone 2, talk-test pace) | finish with 4×15s strides (relaxed-fast, 45–60s walk/jog between) | I18: KB B – Upper & Core (~20', after the easy run, at lunch, or split into two 8–10' desk-break mini-blocks): Halos 2×8 each way | Single-arm press 3×6 each | One-arm row 3×8 each | Russian twist 3×20 | Plank 3×30s
A19: 2 | B19: 46309 | C19: Thu | D19: 1 Re-Entry Base | E19: Quality 2: VO2 Max | F19: 30 | G19: VO2 Max – Zone 5 (RPE 8–9) | H19: WU 10' easy jog + drills | 8×30s @ VO2 effort (~3K–5K race effort) (30s easy jog between) | CD 12' easy | I19: — | J19: Hard but repeatable — last rep ≈ first rep. Jog recoveries, don't stop.
A20: 2 | B20: 46310 | C20: Fri | D20: 1 Re-Entry Base | E20: Rest (KB only) | F20: 0 | G20: — | H20: No running — kettlebell session only. | I20: KB C – Squat, Single-Leg & Carry (~25', no-run day, moderate legs — stop every set ~2 reps shy of failure): Goblet squat 3×10 | Reverse lunge (goblet) 2×8 each | Glute bridge (KB on hips) 3×12 | Suitcase carry 3×30s each | Plank 3×30s
A21: 2 | B21: 46311 | C21: Sat | D21: 1 Re-Entry Base | E21: Easy Run | F21: 30 | G21: Zone 2 + strides (RPE 3–4; strides ~7) | H21: Easy aerobic run 30' (Zone 2, talk-test pace) | finish with 4×15s strides (relaxed-fast, 45–60s walk/jog between) | I21: — | J21: Strides prime the legs for tomorrow's long run.
A22: 2 | B22: 46312 | C22: Sun | D22: 1 Re-Entry Base | E22: Long Run | F22: 60 | G22: Zone 2 – easy (RPE 3–4) | H22: Long run 60' easy (Zone 2). Steady and relaxed — finish feeling you could run 10–15' more. | I22: —
A23: 3 | B23: 46313 | C23: Mon | D23: 1 Re-Entry Base | E23: Rest (KB only) | F23: 0 | G23: — | H23: No running — KB session only. Keep legs moderate (stop 2 reps shy of failure). | I23: KB A – Hinge & Press (~30', no-run day, any time): KB swings (two-hand, one 25) 3×15 | Double-KB deadlift 3×10 | Single-arm press 3×6 each | One-arm row 3×8 each | Suitcase carry 3×30s each
A24: 3 | B24: 46314 | C24: Tue | D24: 1 Re-Entry Base | E24: Quality 1: Threshold | F24: 38 | G24: Threshold – Zone 4 (RPE 6–7) | H24: WU 10' easy jog + drills | 3×6' @ threshold (1' easy jog between) | CD 8' easy | I24: — | J24: Run by effort; see Zones sheet for pace estimates.
A25: 3 | B25: 46315 | C25: Wed | D25: 1 Re-Entry Base | E25: Easy Run | F25: 30 | G25: Zone 2 – easy (RPE 3–4) | H25: Easy aerobic run 30' (Zone 2, talk-test pace) | I25: KB B – Upper & Core (~20', after the easy run, at lunch, or split into two 8–10' desk-break mini-blocks): Halos 2×8 each way | Single-arm press 3×6 each | One-arm row 3×8 each | Russian twist 3×20 | Plank 3×30s
A26: 3 | B26: 46316 | C26: Thu | D26: 1 Re-Entry Base | E26: Quality 2: Sprints/Strides | F26: 35 | G26: Sprint / neuromuscular (RPE 8–9, full recovery) | H26: WU 15' easy jog + drills | 6×8s hill sprints (steep, near-max but relaxed; walk down, ≥90s recovery; use flat 95% accelerations if no hill) | CD 10' easy | I26: — | J26: Quality over quantity: stop if form degrades. Full recovery between reps.
A27: 3 | B27: 46317 | C27: Fri | D27: 1 Re-Entry Base | E27: Rest (KB only) | F27: 0 | G27: — | H27: No running — kettlebell session only. | I27: KB C – Squat, Single-Leg & Carry (~25', no-run day, moderate legs — stop every set ~2 reps shy of failure): Goblet squat 3×10 | Reverse lunge (goblet) 2×8 each | Glute bridge (KB on hips) 3×12 | Suitcase carry 3×30s each | Plank 3×30s
A28: 3 | B28: 46318 | C28: Sat | D28: 1 Re-Entry Base | E28: Easy Run | F28: 30 | G28: Zone 2 + strides (RPE 3–4; strides ~7) | H28: Easy aerobic run 30' (Zone 2, talk-test pace) | finish with 4×15s strides (relaxed-fast, 45–60s walk/jog between) | I28: — | J28: Strides prime the legs for tomorrow's long run.
A29: 3 | B29: 46319 | C29: Sun | D29: 1 Re-Entry Base | E29: Long Run | F29: 65 | G29: Zone 2 – easy (RPE 3–4) | H29: Long run 65' easy (Zone 2). Steady and relaxed — finish feeling you could run 10–15' more. | I29: —
A30: 4 | B30: 46320 | C30: Mon | D30: 1 Re-Entry Base | E30: Rest (KB only) | F30: 0 | G30: — | H30: No running — KB session only. Keep legs moderate (stop 2 reps shy of failure). | I30: KB A – Hinge & Press (~25', no-run day, any time): KB swings (two-hand, one 25) 2×15 | Double-KB deadlift 2×10 | Single-arm press 2×6 each | One-arm row 2×8 each | Suitcase carry 2×30s each — DOWN WEEK: 1 fewer set
A31: 4 | B31: 46321 | C31: Tue | D31: 1 Re-Entry Base | E31: Quality 1: Threshold (light) | F31: 32 | G31: Threshold – Zone 4 (RPE 6–7) | H31: WU 10' easy jog + drills | 2×6' @ threshold (2' easy jog between) | CD 8' easy | I31: — | J31: Run by effort; see Zones sheet for pace estimates.
A32: 4 | B32: 46322 | C32: Wed | D32: 1 Re-Entry Base | E32: Easy Run | F32: 25 | G32: Zone 2 + strides (RPE 3–4; strides ~7) | H32: Easy aerobic run 25' (Zone 2, talk-test pace) | finish with 4×15s strides (relaxed-fast, 45–60s walk/jog between) | I32: KB B – Upper & Core (~15', after the easy run, at lunch, or split into two 8–10' desk-break mini-blocks): Halos 1×8 each way | Single-arm press 2×6 each | One-arm row 2×8 each | Russian twist 2×20 | Plank 2×30s — DOWN WEEK: 1 fewer set
A33: 4 | B33: 46323 | C33: Thu | D33: 1 Re-Entry Base | E33: Quality 2: VO2 Max | F33: 30 | G33: VO2 Max – Zone 5 (RPE 8–9) | H33: WU 10' easy jog + drills | 6×30s @ VO2 effort (~3K–5K race effort) (30s easy jog between) | CD 14' easy | I33: — | J33: Hard but repeatable — last rep ≈ first rep. Jog recoveries, don't stop.
A34: 4 | B34: 46324 | C34: Fri | D34: 1 Re-Entry Base | E34: Rest (KB only) | F34: 0 | G34: — | H34: No running — kettlebell session only. | I34: KB C – Squat, Single-Leg & Carry (~20', no-run day, moderate legs — stop every set ~2 reps shy of failure): Goblet squat 2×10 | Reverse lunge (goblet) 1×8 each | Glute bridge (KB on hips) 2×12 | Suitcase carry 2×30s each | Plank 2×30s — DOWN WEEK: 1 fewer set
A35: 4 | B35: 46325 | C35: Sat | D35: 1 Re-Entry Base | E35: Easy Run | F35: 25 | G35: Zone 2 + strides (RPE 3–4; strides ~7) | H35: Easy aerobic run 25' (Zone 2, talk-test pace) | finish with 4×15s strides (relaxed-fast, 45–60s walk/jog between) | I35: — | J35: Strides prime the legs for tomorrow's long run.
A36: 4 | B36: 46326 | C36: Sun | D36: 1 Re-Entry Base | E36: Long Run | F36: 55 | G36: Zone 2 – easy (RPE 3–4) | H36: Long run 55' easy (Zone 2). Steady and relaxed — finish feeling you could run 10–15' more. | I36: —
A37: 5 | B37: 46327 | C37: Mon | D37: 2 Family-First Maintenance | E37: Rest (KB only) | F37: 0 | G37: — | H37: No running. | I37: KB A – Hinge & Press (~20', no-run day, any time): KB swings (two-hand) 3×15 | Double-KB deadlift 2×10 | Single-arm press 2×6 each | Suitcase carry 2×30s each
A38: 5 | B38: 46328 | C38: Tue | D38: 2 Family-First Maintenance | E38: Quality: Threshold | F38: 38 | G38: Threshold – Zone 4 (RPE 6–7) | H38: WU 10' easy jog + drills | 3×6' @ threshold (1' easy jog between) | CD 8' easy | I38: — | J38: Only quality day this week (family-first block).
A39: 5 | B39: 46329 | C39: Wed | D39: 2 Family-First Maintenance | E39: Rest (KB only) | F39: 0 | G39: — | H39: No running — kettlebell session only. | I39: KB B – Upper & Core (~15', after the easy run, at lunch, or split into two 8–10' desk-break mini-blocks): Halos 2×8 each way | Single-arm press 2×6 each | One-arm row 2×8 each | Plank 2×30s
A40: 5 | B40: 46330 | C40: Thu | D40: 2 Family-First Maintenance | E40: Easy Run | F40: 30 | G40: Zone 2 + strides (RPE 3–4; strides ~7) | H40: Easy aerobic run 30' (Zone 2, talk-test pace) | finish with 4×15s strides (relaxed-fast, 45–60s walk/jog between) | I40: —
A41: 5 | B41: 46331 | C41: Fri | D41: 2 Family-First Maintenance | E41: Rest (KB only) | F41: 0 | G41: — | H41: No running — kettlebell session only. | I41: KB C – Squat, Single-Leg & Carry (~20', no-run day, moderate legs — stop every set ~2 reps shy of failure): Goblet squat 2×10 | Reverse lunge (goblet) 2×8 each | Glute bridge (KB on hips) 2×12 | Plank 2×30s
...

Sheet Kettlebell Plan
A1: Kettlebell Plan — 2 × 25 lb, 3 sessions/week (Mon / Wed / Fri)
A2: Rules: stop every set ~2 reps shy of failure · rest 45–90s between sets · quality running days always win — if a run session leaves you wrecked, shorten the next KB session.
A3: Progression inside each block: weeks 1–3 add the reps/seconds shown (→ = week 1 to week 3 target), week 4 is a down week (1 fewer set). Next block moves up a level.
A4: 25 lb is light for squats and deadlifts: progress with tempo (3s lowering), single-leg work, shorter rests, and double-bell lifts. If a 25 still feels easy for 5×20 swings, consider adding a 35 lb bell.
A5: Workday option: Session B (15–25') splits into two 8–10' mini-blocks. A and C work before/after work or at lunch.
A7: Level / Phase | B7: Weeks | C7: KB A – Hinge & Press (Mon) | D7: KB B – Upper & Core (Wed) | E7: KB C – Squat, Single-Leg & Carry (Fri)
A8: 1. Re-Entry Base | B8: W1–W4 (Oct) | C8: ~30': KB swings (two-hand, one 25) 3×15 | Double-KB deadlift 3×10 | Single-arm press 3×6 each | One-arm row 3×8 each | Suitcase carry 3×30s each | D8: ~20': Halos 2×8 each way | Single-arm press 3×6 each | One-arm row 3×8 each | Russian twist 3×20 | Plank 3×30s | E8: ~25': Goblet squat 3×10 | Reverse lunge (goblet) 2×8 each | Glute bridge (KB on hips) 3×12 | Suitcase carry 3×30s each | Plank 3×30s
A9: 2. Family-First Maintenance | B9: W5–W13 (Nov–Dec) | C9: ~20': KB swings (two-hand) 3×15 | Double-KB deadlift 2×10 | Single-arm press 2×6 each | Suitcase carry 2×30s each | D9: ~15': Halos 2×8 each way | Single-arm press 2×6 each | One-arm row 2×8 each | Plank 2×30s | E9: ~20': Goblet squat 2×10 | Reverse lunge (goblet) 2×8 each | Glute bridge (KB on hips) 2×12 | Plank 2×30s
A10: 3. Base Build | B10: W14–W21 (Jan–Feb) | C10: ~35': KB swings (two-hand) 4×15→19 | Double-KB deadlift (3s lowering) 3×8→10 | Double-KB press 3×5→7 | One-arm row 3×8→10 each | Turkish get-up 2×2 each | Double farmer carry 3×40→50s | D10: ~20': Halos 2×8 each way | Double-KB press 3×5→7 | Double-KB bent-over row 3×8→10 | Turkish get-up 2×2 each | Russian twist 3×20→24 | Plank 3×40→50s | E10: ~30': Double-KB front squat 3×8→10 | Reverse lunge (double rack) 3×6→8 each | Single-leg glute bridge 3×8→10 each | Calf raise (hold KB) 3×12→16 | Suitcase carry 3×40→50s each | Side plank 3×20→30s each
A11: 4. Build I | B11: W22–W29 (Mar–Apr) | C11: ~40': One-arm swings 4×10→12 each | Single-leg RDL (one KB) 3×8→10 each | Double-KB press 4×5→7 | Renegade row 3×5→7 each | Turkish get-up 3×2 each | Double farmer carry 4×40→50s | D11: ~25': Halos 3×8 each way | Double-KB press 4×5→7 | Double-KB bent-over row 4×8→10 | Turkish get-up 3×2 each | Windmill 2×5 each | Dead bug 3×8 each | E11: ~35': Double-KB front squat 4×8→10 | Rear-foot-elevated split squat (goblet) 3×6→8 each | Single-leg calf raise 3×10→14 each | Step-up (stair/low box, double KB) 3×6→8 each | Rack carry (one KB) 3×40→50s each | Side plank 3×30→40s each
A12: 5. Build II | B12: W30–W41 (Apr–Jul) | C12: ~40': One-arm swings 5×10→12 each | Single-leg RDL (one KB) 4×8→10 each | Double-KB push press 4×5→7 | Renegade row 3×6→8 each | Turkish get-up 3×3 each | Double farmer carry 4×45→55s | D12: ~25': Halos 3×8 each way | Double-KB push press 4×5→7 | Double-KB bent-over row 4×10→12 | Bottoms-up press 2×5 each | Windmill 3×5 each | Russian twist 3×24→28 | E12: ~35': Double-KB front squat (3s lowering) 4×8→10 | Rear-foot-elevated split squat (goblet) 4×6→8 each | Single-leg calf raise 3×12→16 each | Step-up (stair/low box, double KB) 3×8→10 each | Rack carry (one KB) 3×45→55s each | Side plank 3×35→45s each
A13: 6. Half-Marathon Block | B13: W42–W52 (Jul–Oct) | C13: ~35': One-arm swings 4×10→12 each | Single-leg RDL (one KB) 3×10 each | Double-KB press 3×6 | Renegade row 3×6 each | Turkish get-up 2×3 each | Double farmer carry 4×45s | D13: ~20': Halos 2×8 each way | Double-KB press 3×6 | Double-KB bent-over row 3×10 | Turkish get-up 2×3 each | Windmill 2×5 each | Plank 3×45s | E13: ~30': Double-KB front squat 3×8 | Rear-foot-elevated split squat (goblet) 3×6 each | Single-leg calf raise 3×12 each | Step-up (stair/low box, double KB) 3×8 each | Rack carry (one KB) 3×45s each | Side plank 3×35s each

Sheet Zones & Sessions
A1: Intensity Zones & Session Library
A3: Pace calculator (update after your Week 18 time trial)
A4: 20-min time trial distance (miles) | B4: 2.9 | C4: ← YELLOW = edit me. 2.9 mi is a STARTING ASSUMPTION (≈6:54/mi, ≈21:25 5K), inferred from your 60' @ 8:30 comfortable run. Replace with your real 20' TT distance on 2/4/2027.
A5: 20-min TT pace (sec/mi) | B5: =1200/B4 -> 413.7931
A6: 20-min TT pace (min:sec/mi) | B6: =TEXT(B5/86400,"m:ss") -> 6:54
A8: Intensity System | B8: Purpose | C8: Effort / RPE | D8: Pace estimate (min/mi) | E8: Rule of thumb vs. TT pace | F8: Typical sessions | G8: Frequency
A9: Easy – Zone 2 | B9: Aerobic base, durability, recovery | C9: RPE 3–4, full sentences | D9: =TEXT(($B$5+(100))/86400,"m:ss")&" – "&TEXT(($B$5+(150))/86400,"m:ss") -> 8:34 – 9:24 | E9: TT pace + 100–150 sec/mi (slower is fine; go by talk test) | F9: Easy runs, long run, warm-ups/cool-downs | G9: Most of the week (3–4 runs + long run)
A10: Lactate Threshold | B10: Raise sustainable speed (half-marathon/10K engine) | C10: RPE 6–7, comfortably hard | D10: =TEXT(($B$5+(15))/86400,"m:ss")&" – "&TEXT(($B$5+(20))/86400,"m:ss") -> 7:09 – 7:14 | E10: TT pace + 15–20 sec/mi | F10: Cruise intervals (3×8'/1'), 2×12'/2', 20–25' tempo | G10: Every week (Tuesday)
A11: VO2 Max | B11: Raise aerobic ceiling (5K speed) | C11: RPE 8–9, hard but repeatable | D11: =TEXT(($B$5+(-10))/86400,"m:ss")&" – "&TEXT(($B$5+(-5))/86400,"m:ss") -> 6:44 – 6:49 | E11: TT pace − 5 to 10 sec/mi (≈3K–5K effort) | F11: 30/30s, 1' reps, 2–4' reps, 5×3' | G11: Every other week (Thursday, A weeks)
A12: Short Sprints / Accelerations | B12: Recruit fast-twitch fibers, running economy, form | C12: RPE 8–9 for 8–20s, full recovery | D12: Effort-based (not paced) | E12: Fast and relaxed — roughly mile-race effort or hill sprint | F12: Hill sprints 6–8×8–10s, flat 6–8×15–20s; 4–5 strides after select easy runs | G12: Every other week (Thursday, B weeks) + strides weekly
A14: 14-day rotation
A15: Week A (even weeks) | B15: Tue: Threshold | Thu: VO2 Max | Wed + Sat: easy with strides
A16: Week B (odd weeks) | B16: Tue: Threshold | Thu: Sprints/Strides | Sat: easy with strides
A17: Down weeks (every 4th) | B17: Same structure, ~25–30% less volume and reps. Race/test weeks replace Thu or Sat.
A18: Kettlebell placement | B18: Mon: KB A (hinge & press) | Wed: KB B (upper & core, workday-friendly) | Fri: KB C (squat/single-leg/carry, moderate) | None on Tue/Thu quality days or before the long run
A20: Paces are estimates built from the assumption in B4. Always let effort/RPE win over the watch on hot, hilly, or tired days.
